Workbook
Name CIQWBGuid: "2cd8126d-26c3-430c-b7fa-a069e3a1fc62"
Name IQ_CH: 110000
Name IQ_CQ: 5000
Name IQ_CY: 10000
Name IQ_DAILY: 500000
Name IQ_DNTM: 700000
Name IQ_FH: 100000
Name IQ_FQ: 500
Name IQ_FWD_CY: 10001
Name IQ_FWD_CY1: 10002
Name IQ_FWD_CY2: 10003
Name IQ_FWD_FY: 1001
Name IQ_FWD_FY1: 1002
Name IQ_FWD_FY2: 1003
Name IQ_FWD_Q: 501
Name IQ_FWD_Q1: 502
Name IQ_FWD_Q2: 503
Name IQ_FY: 1000
Name IQ_LATESTK: 1000
Name IQ_LATESTQ: 500
Name IQ_LTM: 2000
Name IQ_LTMMONTH: 120000
Name IQ_MONTH: 15000
Name IQ_MTD: 800000
Name IQ_NAMES_REVISION_DATE_: 43412.7003240741
Name IQ_NTM: 6000
Name IQ_QTD: 750000
Name IQ_TODAY: 0
Name IQ_WEEK: 50000
Name IQ_YTD: 3000
Name IQ_YTDMONTH: 130000

Sheet M&A Assumptions & Analysis
A1: ="Merger Assumptions for "&D6&" & "&D7 -> Merger Assumptions for Online Company Inc & Brick 'n' Mortar Co
A3: Assumptions
A5: Transaction Inputs | F5: Scenarios
A6: Acquirer Name | D6: Online Company Inc | F6: Scenario # | G6: LIVE --> | H6: 1 | I6: 1 | J6: =+I6+1 -> 2 | K6: =+J6+1 -> 3 | L6: =+K6+1 -> 4 | M6: =+L6+1 -> 5
A7: Target Name | D7: Brick 'n' Mortar Co
A8: Acquirer Share Price | D8: ='[1]M&A Assumptions'!$C$5 -> 11.75 | F8: Synergies
A9: Target Share Price | D9: ='Target Model'!C159 -> 17.3 | F9: Revenue enhancement | H9: =+OFFSET(I9,0,$H$6-1) -> 5500 | I9: ='[2]M&A Assumptions'!$C$22 -> 5500 | J9: ='[2]M&A Assumptions'!$D$22 -> 6000 | K9: ='[2]M&A Assumptions'!$E$22 -> 6000 | L9: ='[2]M&A Assumptions'!$F$22 -> 6500 | M9: ='[2]M&A Assumptions'!$G$22 -> 6500
A10: Transaction Close Date | D10: 45838 | F10: COGS savings | H10: =+OFFSET(I10,0,$H$6-1) -> 875 | I10: ='[2]M&A Assumptions'!$C$23 -> 875 | J10: ='[2]M&A Assumptions'!$D$23 -> 875 | K10: ='[2]M&A Assumptions'!$E$23 -> 875 | L10: ='[2]M&A Assumptions'!$F$23 -> 875 | M10: ='[2]M&A Assumptions'!$G$23 -> 875
A11: Financial Reporting Units | D11: $'000s | F11: Marketing savings | H11: =+OFFSET(I11,0,$H$6-1) -> 1250 | I11: ='[2]M&A Assumptions'!$C$24 -> 1250 | J11: ='[2]M&A Assumptions'!$C$24 -> 1250 | K11: ='[2]M&A Assumptions'!$C$24 -> 1250 | L11: ='[2]M&A Assumptions'!$C$24 -> 1250 | M11: ='[2]M&A Assumptions'!$C$24 -> 1250
A12: Currency | D12: USD | F12: General & Admin savings | H12: =+OFFSET(I12,0,$H$6-1) -> 1000 | I12: ='[2]M&A Assumptions'!$C$25 -> 1000 | J12: ='[2]M&A Assumptions'!$C$25 -> 1000 | K12: ='[2]M&A Assumptions'!$C$25 -> 1000 | L12: ='[2]M&A Assumptions'!$C$25 -> 1000 | M12: ='[2]M&A Assumptions'!$C$25 -> 1000
A14: Restructuring Charges | D14: ='[2]M&A Assumptions'!$C$11 -> 2000 | F14: Synergies in Year 1 (full yr.) | H14: =+OFFSET(I14,0,$H$6-1) -> 0.3 | I14: ='[2]M&A Assumptions'!$C$27 -> 0.3 | J14: ='[2]M&A Assumptions'!$C$27 -> 0.3 | K14: ='[2]M&A Assumptions'!$C$27 -> 0.3 | L14: ='[2]M&A Assumptions'!$C$27 -> 0.3 | M14: ='[2]M&A Assumptions'!$C$27 -> 0.3
A15: Equity Issuance Fees | D15: ='[2]M&A Assumptions'!$C$12 -> 0.03 | F15: Synergies in Year 2 | H15: =+OFFSET(I15,0,$H$6-1) -> 0.65 | I15: ='[2]M&A Assumptions'!$C$28 -> 0.65 | J15: ='[2]M&A Assumptions'!$C$28 -> 0.65 | K15: ='[2]M&A Assumptions'!$C$28 -> 0.65 | L15: ='[2]M&A Assumptions'!$C$28 -> 0.65 | M15: ='[2]M&A Assumptions'!$C$28 -> 0.65
A16: Debt Issuance Fees | D16: ='[2]M&A Assumptions'!$C$13 -> 0.03 | F16: Synergies in Years 3+ | H16: =+OFFSET(I16,0,$H$6-1) -> 1 | I16: ='[2]M&A Assumptions'!$C$29 -> 1 | J16: ='[2]M&A Assumptions'!$C$29 -> 1 | K16: ='[2]M&A Assumptions'!$C$29 -> 1 | L16: ='[2]M&A Assumptions'!$C$29 -> 1 | M16: ='[2]M&A Assumptions'!$C$29 -> 1
A17: Other Closing Costs | D17: ='[2]M&A Assumptions'!$C$14 -> 2000
F18: Financing
A19: Replace Target Debt | D19: No | F19: Debt Tranche
A20: Replace Acquirer Debt | D20: Yes | F20: Senior Debt A | H20: =+OFFSET(I20,0,$H$6-1) -> 0 | I20: 0 | J20: ='[2]M&A Assumptions'!$D$33 -> 100000 | K20: ='[2]M&A Assumptions'!$E$33 -> 100000 | L20: ='[2]M&A Assumptions'!$F$33 -> 100000 | M20: ='[2]M&A Assumptions'!$G$33 -> 100000
F21: Senior Debt B | H21: =+OFFSET(I21,0,$H$6-1) -> 0 | I21: ='[2]M&A Assumptions'!$C$34 -> 0 | J21: ='[2]M&A Assumptions'!$D$34 -> 0 | K21: ='[2]M&A Assumptions'!$E$34 -> 50000 | L21: ='[2]M&A Assumptions'!$F$34 -> 50000 | M21: ='[2]M&A Assumptions'!$G$34 -> 50000
A22: Acquirer FD Shares Outstanding | D22: ='[1]M&A Assumptions'!$C$16 -> 50000 | F22: Subordinated Debt | H22: =+OFFSET(I22,0,$H$6-1) -> 0 | I22: ='[2]M&A Assumptions'!$C$35 -> 0 | J22: ='[2]M&A Assumptions'!$D$35 -> 0 | K22: ='[2]M&A Assumptions'!$E$35 -> 0 | L22: ='[2]M&A Assumptions'!$F$35 -> 25000 | M22: ='[2]M&A Assumptions'!$G$35 -> 25000
A23: Target FD Share Outstanding | D23: 25000 | F23: Interest Rate
A24: Shares Issued | D24: =+M38/D28 -> 42757.361 | F24: Senior Debt A | H24: =+OFFSET(I24,0,$H$6-1) -> 0.055 | I24: ='[2]M&A Assumptions'!$C$37 -> 0.055 | J24: ='[2]M&A Assumptions'!$C$37 -> 0.055 | K24: ='[2]M&A Assumptions'!$C$37 -> 0.055 | L24: ='[2]M&A Assumptions'!$C$37 -> 0.055 | M24: ='[2]M&A Assumptions'!$C$37 -> 0.055
A25: Pro Forma Shares Outstanding | D25: =+D22+D24 -> 92757.361 | F25: Senior Debt B | H25: =+OFFSET(I25,0,$H$6-1) -> 0.0575 | I25: ='[2]M&A Assumptions'!$C$38 -> 0.0575 | J25: ='[2]M&A Assumptions'!$C$38 -> 0.0575 | K25: ='[2]M&A Assumptions'!$C$38 -> 0.0575 | L25: ='[2]M&A Assumptions'!$C$38 -> 0.0575 | M25: ='[2]M&A Assumptions'!$C$38 -> 0.0575
F26: Subordinated Debt | H26: =+OFFSET(I26,0,$H$6-1) -> 0.0825 | I26: ='[2]M&A Assumptions'!$C$39 -> 0.0825 | J26: ='[2]M&A Assumptions'!$C$39 -> 0.0825 | K26: ='[2]M&A Assumptions'!$C$39 -> 0.0825 | L26: ='[2]M&A Assumptions'!$C$39 -> 0.0825 | M26: ='[2]M&A Assumptions'!$C$39 -> 0.0825
A27: Share Issuance Discount | D27: ='[2]M&A Assumptions'!$C$19 -> 0.01
A28: Share Issuance Price | D28: =+D8*(1-D27) -> 11.6325
F29: Transaction
F30: Takeover Premium | H30: =+OFFSET(I30,0,$H$6-1) -> 0.15 | I30: ='[2]M&A Assumptions'!$C$42 -> 0.15 | J30: ='[2]M&A Assumptions'!$D$42 -> 0.15 | K30: ='[2]M&A Assumptions'!$E$42 -> 0.2 | L30: ='[2]M&A Assumptions'!$F$42 -> 0.25 | M30: ='[2]M&A Assumptions'!$G$42 -> 0.3
A31: Purchase Price | F31: Cash Consideration | H31: =+OFFSET(I31,0,$H$6-1) -> 0 | I31: ='[2]M&A Assumptions'!$C$43 -> 0 | J31: ='[2]M&A Assumptions'!$D$43 -> 0.2 | K31: ='[2]M&A Assumptions'!$E$43 -> 0.4 | L31: ='[2]M&A Assumptions'!$F$43 -> 0.5 | M31: ='[2]M&A Assumptions'!$G$43 -> 0.55
A32: Target Share Price | D32: =+D9 -> 17.3
A33: Takeover Premium | D33: =+H30 -> 0.15
A34: Offer Price | D34: =+D32*(1+D33) -> 19.895
F35: Sources & Uses of Cash
A36: Acquirer Share Price | D36: =+D8 -> 11.75 | F36: Sources of Cash
A37: Share Exchange Ratio | D37: =+D34/D36 -> 1.6931915 | F37: Cash | I37: =+M44-SUM(I38:I43) -> 46921.25 | K37: Cash Consideration | M37: =+D41*H31 -> 0
F38: Stock Issued | I38: =+M38 -> 497375 | K38: Stock Consideration | M38: =+D41-M37 -> 497375
A39: Target Shares Outstanding | D39: =+D23 -> 25000 | F39: Debt Issued | I39: =+SUM(H20:H22) -> 0 | K39: Target Debt - Replace (ST+LT) | M39: =+IF(D19="Yes", D42,0) -> 0
A40: Offer Price | D40: =+D34 -> 19.895 | K40: Acquirer Debt - Replace (ST+LT) | M40: =+IF(D20="Yes",'Acquirer Model'!O90+'Acquirer Model'!O93,0) -> 30000
A41: Purchase Price | D41: =+D39*D40 -> 497375 | K41: Debt Financing Fees | M41: =+D16*SUM(H20:H22) -> 0
A42: Target Debt (Total Debt ST + LT) | D42: =+'Target Model'!O90+'Target Model'!O93 -> 16801.075 | K42: Equity Financing Fees | M42: =+D15*M38 -> 14921.25
A43: Target Cash | D43: =+'Target Model'!O81 -> 77532.337 | K43: Other Closing Costs | M43: =+D17 -> 2000
...

Sheet Pro Forma Model
I1: Forecast Period
A2: Pro Forma Model | H2: CLOSE | I2: ='Acquirer Model'!I2 -> 2025 | J2: ='Acquirer Model'!J2 -> 2026 | K2: ='Acquirer Model'!K2 -> 2027 | L2: ='Acquirer Model'!L2 -> 2028 | M2: ='Acquirer Model'!M2 -> 2029 | N2: ='Acquirer Model'!N2 -> 2030
A3: Balance Sheet Check | H3: =IFERROR(IF(ABS(H71)>1,"ERROR","ok"),"ok") -> ok | I3: =IFERROR(IF(ABS(I71)>1,"ERROR","ok"),"ok") -> ok | J3: =IFERROR(IF(ABS(J71)>1,"ERROR","ok"),"ok") -> ok | K3: =IFERROR(IF(ABS(K71)>1,"ERROR","ok"),"ok") -> ok | L3: =IFERROR(IF(ABS(L71)>1,"ERROR","ok"),"ok") -> ok | M3: =IFERROR(IF(ABS(M71)>1,"ERROR","ok"),"ok") -> ok | N3: =IFERROR(IF(ABS(N71)>1,"ERROR","ok"),"ok") -> ok
A4: End of Period | H4: 45838 | I4: 46022 | J4: 46387 | K4: 46752 | L4: 47118 | M4: 47483 | N4: 47848
A5: Days in Period | H5: =I4-H4 -> 184 | I5: =365-H5 -> 181 | J5: 365 | K5: 365 | L5: 366 | M5: 365 | N5: 365
A6: Fraction of Year | H6: 0.5 | I6: 0.5 | J6: 1 | K6: 1 | L6: 1 | M6: 1 | N6: 1
A8: Assumptions
A11: Debt Amortization Schedule | G11: Check
A12: Senior Debt A | G12: =SUM(H12:N12) -> 1 | H12: 0 | I12: 0.25 | J12: 0.25 | K12: 0.25 | L12: 0.25 | M12: 0 | N12: 0
A13: Senior Debt B | G13: =SUM(H13:N13) -> 1 | H13: 0 | I13: 0 | J13: 0.2 | K13: 0.2 | L13: 0.2 | M13: 0.2 | N13: 0.2
A14: Subordinated Debt | G14: =SUM(H14:N14) -> 1 | H14: 0 | I14: 0 | J14: 0 | K14: 0 | L14: 0 | M14: 0 | N14: 1
A17: Revenue Growth (% Change)
A18: Cost of Goods Sold (% of Revenue)
A19: Marketing, Advertising & Promotion (% of Revenue)
A21: Depreciation & Amortization (% of PP&E) | I21: 0.2 | J21: 0.2 | K21: 0.2 | L21: 0.2 | M21: 0.2 | N21: 0.2
A22: Tax Rate (% of Earnings Before Tax) | I22: 0.3 | J22: 0.3 | K22: 0.3 | L22: 0.3 | M22: 0.3 | N22: 0.3
A23: Accounts Receivable (Days) | I23: 18 | J23: 18 | K23: 18 | L23: 18 | M23: 18 | N23: 18
A24: Inventory (Days) | I24: 80 | J24: 90 | K24: 100 | L24: 100 | M24: 100 | N24: 100
A25: Accounts Payable (Days) | I25: 37 | J25: 37 | K25: 37 | L25: 37 | M25: 37 | N25: 37
A27: Equity Issued (Repaid) ($000's) | I27: 0 | J27: 0 | K27: 0 | L27: 0 | M27: 0 | N27: 0
A28: Dividends Paid | I28: 0 | J28: 0 | K28: 0 | L28: 500 | M28: 500 | N28: 500
A31: Income Statement
A33: Revenue | I33: =+I208 -> 131476.29 | J33: =+J208 -> 295753.01 | K33: =+K208 -> 329321.69 | L33: =+L208 -> 361814.58 | M33: =+M208 -> 390319.75 | N33: =+N208 -> 415771.31
A34: Cost of Goods Sold (COGS) | I34: =+I214 -> 55220.042 | J34: =+J214 -> 123968.42 | K34: =+K214 -> 137757.03 | L34: =+L214 -> 152587.76 | M34: =+M214 -> 167227.16 | N34: =+N214 -> 178399.98
A35: Gross Profit | I35: =+I33-I34 -> 76256.249 | J35: =+J33-J34 -> 171784.59 | K35: =+K33-K34 -> 191564.66 | L35: =+L33-L34 -> 209226.82 | M35: =+M33-M34 -> 223092.59 | N35: =+N33-N34 -> 237371.33
A36: Expenses
A37: Marketing, Advertising & Promotion | I37: =+I220 -> 21865.453 | J37: =+J220 -> 48505.823 | K37: =+K220 -> 53313.746 | L37: =+L220 -> 57947.718 | M37: =+M220 -> 62683.536 | N37: =+N220 -> 66921.152
A38: General & Administrative | I38: =+I226 -> 11000 | J38: =+J226 -> 21700 | K38: =+K226 -> 21350 | L38: =+L226 -> 21000 | M38: =+M226 -> 21000 | N38: =+N226 -> 21000
A39: Depreciation & Amortization | I39: =+I111 -> 4126.8945 | J39: =+J111 -> 9503.4101 | K39: =+K111 -> 11752.728 | L39: =+L111 -> 13552.182 | M39: =+M111 -> 14991.746 | N39: =+N111 -> 16143.397
A40: Interest | I40: =+I160 -> 672.04 | J40: =+J160 -> 1344.08 | K40: =+K160 -> 1344.08 | L40: =+L160 -> 1344.08 | M40: =+M160 -> 1344.08 | N40: =+N160 -> 1344.08
A41: Total Expenses | I41: =SUM(I37:I40) -> 37664.387 | J41: =SUM(J37:J40) -> 81053.313 | K41: =SUM(K37:K40) -> 87760.554 | L41: =SUM(L37:L40) -> 93843.981 | M41: =SUM(M37:M40) -> 100019.36 | N41: =SUM(N37:N40) -> 105408.63
A42: Earnings Before Tax | I42: =+I35-I41 -> 38591.862 | J42: =+J35-J41 -> 90731.281 | K42: =+K35-K41 -> 103804.11 | L42: =+L35-L41 -> 115382.84 | M42: =+M35-M41 -> 123073.23 | N42: =+N35-N41 -> 131962.7
A44: Taxes | I44: =+IF(I42>0,I42*I22,0) -> 11577.559 | J44: =+IF(J42>0,J42*J22,0) -> 27219.384 | K44: =+IF(K42>0,K42*K22,0) -> 31141.233 | L44: =+IF(L42>0,L42*L22,0) -> 34614.853 | M44: =+IF(M42>0,M42*M22,0) -> 36921.97 | N44: =+IF(N42>0,N42*N22,0) -> 39588.811
A45: Net Earnings | I45: =+I42-I44 -> 27014.303 | J45: =+J42-J44 -> 63511.896 | K45: =+K42-K44 -> 72662.876 | L45: =+L42-L44 -> 80767.99 | M45: =+M42-M44 -> 86151.263 | N45: =+N42-N44 -> 92373.893
A48: Balance Sheet
A50: Assets
A51: Cash | H51: =+'M&A Assumptions & Analysis'!M66 -> 178399.36 | I51: =+I95 -> 111704.14 | J51: =+J95 -> 157577.04 | K51: =+K95 -> 213810.86 | L51: =+L95 -> 282839.52 | M51: =+M95 -> 358679.29 | N51: =+N95 -> 432762.97
A52: Accounts Receivable | H52: =+'M&A Assumptions & Analysis'!M67 -> 8590.8726 | I52: =+I33*I23/I5 -> 13074.99 | J52: =+J33*J23/J5 -> 14585.08 | K52: =+K33*K23/K5 -> 16240.522 | L52: =+L33*L23/L5 -> 17794.16 | M52: =+M33*M23/M5 -> 19248.645 | N52: =+N33*N23/N5 -> 20503.791
A53: Inventory | H53: =+'M&A Assumptions & Analysis'!M68 -> -62482.826 | I53: =+I34*I24/I5 -> 24406.649 | J53: =+J34*J24/J5 -> 30567.555 | K53: =+K34*K24/K5 -> 37741.651 | L53: =+L34*L24/L5 -> 41690.644 | M53: =+M34*M24/M5 -> 45815.659 | N53: =+N34*N24/N5 -> 48876.706
A54: Current Assets | H54: =SUM(H51:H53) -> 124507.41 | I54: =SUM(I51:I53) -> 149185.78 | J54: =SUM(J51:J53) -> 202729.67 | K54: =SUM(K51:K53) -> 267793.03 | L54: =SUM(L51:L53) -> 342324.33 | M54: =SUM(M51:M53) -> 423743.59 | N54: =SUM(N51:N53) -> 502143.47
...

Sheet Acquirer Model
D1: Historical Results | I1: Forecast Period | O1: Stub
A2: ='M&A Assumptions & Analysis'!D6& " Model" -> Online Company Inc Model | D2: 2020 | E2: =+D2+1 -> 2021 | F2: =+E2+1 -> 2022 | G2: =+F2+1 -> 2023 | H2: =+G2+1 -> 2024 | I2: =+H2+1 -> 2025 | J2: =+I2+1 -> 2026 | K2: =+J2+1 -> 2027 | L2: =+K2+1 -> 2028 | ... N2: =+M2+1 -> 2030 | O2: =+O4 -> 45838 | P2: =+P4 -> 46022
A3: Balance Sheet Check | D3: =IFERROR(IF(ABS(D101)>1,"ERROR","ok"),"ok") -> ok | E3: =IFERROR(IF(ABS(E101)>1,"ERROR","ok"),"ok") -> ok | F3: =IFERROR(IF(ABS(F101)>1,"ERROR","ok"),"ok") -> ok | G3: =IFERROR(IF(ABS(G101)>1,"ERROR","ok"),"ok") -> ok | H3: =IFERROR(IF(ABS(H101)>1,"ERROR","ok"),"ok") -> ok | I3: =IFERROR(IF(ABS(I101)>1,"ERROR","ok"),"ok") -> ok | J3: =IFERROR(IF(ABS(J101)>1,"ERROR","ok"),"ok") -> ok | K3: =IFERROR(IF(ABS(K101)>1,"ERROR","ok"),"ok") -> ok | ... N3: =IFERROR(IF(ABS(N101)>1,"ERROR","ok"),"ok") -> ok
A4: End of Period | D4: 44196 | E4: =EOMONTH(D4,12) -> 44561 | F4: =EOMONTH(E4,12) -> 44926 | G4: =EOMONTH(F4,12) -> 45291 | H4: =EOMONTH(G4,12) -> 45657 | I4: =EOMONTH(H4,12) -> 46022 | J4: =EOMONTH(I4,12) -> 46387 | K4: =EOMONTH(J4,12) -> 46752 | L4: =EOMONTH(K4,12) -> 47118 | ... N4: =EOMONTH(M4,12) -> 47848 | O4: =+'M&A Assumptions & Analysis'!D10 -> 45838 | P4: =+EOMONTH(O4,P6*12) -> 46022
A5: Days in Period | D5: 366 | E5: =E4-D4 -> 365 | F5: =F4-E4 -> 365 | G5: =G4-F4 -> 365 | H5: =H4-G4 -> 366 | I5: =I4-H4 -> 365 | J5: =J4-I4 -> 365 | K5: =K4-J4 -> 365 | L5: =L4-K4 -> 366 | ... N5: =N4-M4 -> 365 | O5: =+O4-H4 -> 181 | P5: =+P4-O4 -> 184
A6: Fraction of Year | D6: 1 | E6: =D6 -> 1 | F6: =E6 -> 1 | G6: =F6 -> 1 | H6: =G6 -> 1 | I6: =H6 -> 1 | J6: =I6 -> 1 | K6: =J6 -> 1 | L6: =K6 -> 1 | ... N6: =M6 -> 1 | O6: 0.5 | P6: =1-O6 -> 0.5
A8: Assumptions
H10: LIVE SCENARIO | I10: 1
A12: SCENARIO 1
A13: Revenue Growth (% Change) | I13: 0.1 | J13: 0.1 | K13: 0.1 | L13: 0.09 | M13: 0.08 | N13: 0.07 | O13: 0.1 | P13: 0.1
A14: Cost of Goods Sold (% of Revenue) | D14: 0.37 | E14: 0.38 | F14: 0.39 | G14: 0.4 | H14: 0.41 | I14: 0.42 | J14: 0.43 | K14: 0.44 | L14: 0.45 | M14: 0.46 | N14: 0.46 | O14: 0.42 | P14: 0.42
A15: Salaries and Benefits (% of Revenue) | I15: 0.17 | J15: 0.17 | K15: 0.17 | L15: 0.17 | M15: 0.17 | N15: 0.17 | O15: 0.17 | P15: 0.17
A16: Rent and Overhead ($000's) | I16: 15000 | J16: 15000 | K16: 15000 | L16: 15000 | M16: 15000 | N16: 15000 | O16: 15000 | P16: 15000
A17: Depreciation & Amortization (% of PP&E) | I17: 0.2 | J17: 0.2 | K17: 0.2 | L17: 0.2 | M17: 0.2 | N17: 0.2 | O17: 0.2 | P17: 0.2
A18: Interest (% of Debt) | I18: 0.1 | J18: 0.1 | K18: 0.1 | L18: 0.1 | M18: 0.1 | N18: 0.1 | O18: 0.1 | P18: 0.1
A19: Tax Rate (% of Earnings Before Tax) | I19: 0.28 | J19: 0.28 | K19: 0.28 | L19: 0.28 | M19: 0.28 | N19: 0.28 | O19: 0.28 | P19: 0.28
A20: Accounts Receivable (Days) | I20: 18 | J20: 18 | K20: 18 | L20: 18 | M20: 18 | N20: 18 | O20: 18 | P20: 18
A21: Inventory (Days) | I21: 80 | J21: 90 | K21: 100 | L21: 100 | M21: 100 | N21: 100 | O21: 80 | P21: 80
A22: Accounts Payable (Days) | I22: 37 | J22: 37 | K22: 37 | L22: 37 | M22: 37 | N22: 37 | O22: 37 | P22: 37
A23: Capital Expenditures ($000's) | D23: 15000 | E23: 15000 | F23: 15000 | G23: 15000 | H23: 15000 | I23: 15000 | J23: 15000 | K23: 15000 | L23: 15000 | M23: 15000 | N23: 15000 | O23: 15000 | P23: 15000
A24: Debt Issuance (Repayment) ($000's) | I24: 0 | J24: 0 | K24: -20000 | L24: 0 | M24: 0 | N24: 0 | O24: 0 | P24: 0
A25: Equity Issued (Repaid) ($000's) | I25: 0 | J25: 0 | K25: 0 | L25: 0 | M25: 0 | N25: 0 | O25: 0 | P25: 0
A26: Payment of Dividends | I26: 0 | J26: 0 | K26: 0 | L26: 0 | M26: 200 | N26: 200 | O26: 0 | P26: 0
A28: SCENARIO 2
A29: Revenue Growth (% Change) | I29: 0.05 | J29: 0.045 | K29: 0.04 | L29: 0.035 | M29: 0.03 | N29: 0.03 | O29: 0.05 | P29: 0.05
A30: Cost of Goods Sold (% of Revenue) | I30: 0.37 | J30: 0.37 | K30: 0.36 | L30: 0.36 | M30: 0.35 | N30: 0.35 | O30: 0.37 | P30: 0.37
A31: Salaries and Benefits (% of Revenue) | I31: 0.17 | J31: 0.17 | K31: 0.17 | L31: 0.17 | M31: 0.17 | N31: 0.17 | O31: 0.17 | P31: 0.17
A32: Rent and Overhead ($000's) | I32: 10000 | J32: 10000 | K32: 10000 | L32: 10000 | M32: 10000 | N32: 10000 | O32: 10000 | P32: 10000
A33: Depreciation & Amortization (% of PP&E) | I33: 0.2 | J33: 0.2 | K33: 0.2 | L33: 0.2 | M33: 0.2 | N33: 0.2 | O33: 0.2 | P33: 0.2
A34: Interest (% of Debt) | I34: 0.05 | J34: 0.05 | K34: 0.05 | L34: 0.05 | M34: 0.05 | N34: 0.05 | O34: 0.05 | P34: 0.05
A35: Tax Rate (% of Earnings Before Tax) | I35: 0.28 | J35: 0.28 | K35: 0.28 | L35: 0.28 | M35: 0.28 | N35: 0.28 | O35: 0.28 | P35: 0.28
A36: Accounts Receivable (Days) | I36: 18 | J36: 18 | K36: 18 | L36: 18 | M36: 18 | N36: 18 | O36: 18 | P36: 18
A37: Inventory (Days) | I37: 73 | J37: 73 | K37: 73 | L37: 73 | M37: 73 | N37: 73 | O37: 73 | P37: 73
A38: Accounts Payable (Days) | I38: 37 | J38: 37 | K38: 37 | L38: 37 | M38: 37 | N38: 37 | O38: 37 | P38: 37
A39: Capital Expenditures ($000's) | I39: 15000 | J39: 15000 | K39: 15000 | L39: 15000 | M39: 15000 | N39: 15000 | O39: 15000 | P39: 15000
A40: Debt Issuance (Repayment) ($000's) | I40: 0 | J40: 0 | K40: -20000 | L40: 0 | M40: 0 | N40: 0 | O40: 0 | P40: 0
... A42: Payment of Dividends | I42: 0 | J42: 0 | K42: 0 | L42: 0 | M42: 100 | N42: 100 | O42: 0 | P42: 0
A44: LIVE SCENARIO
A45: Revenue Growth (% Change) | I45: =CHOOSE($I$10,I13,I29) -> 0.1 | J45: =CHOOSE($I$10,J13,J29) -> 0.1 | K45: =CHOOSE($I$10,K13,K29) -> 0.1 | L45: =CHOOSE($I$10,L13,L29) -> 0.09 | M45: =CHOOSE($I$10,M13,M29) -> 0.08 | N45: =CHOOSE($I$10,N13,N29) -> 0.07 | O45: =CHOOSE($I$10,O13,O29) -> 0.1 | P45: =CHOOSE($I$10,P13,P29) -> 0.1
A46: Cost of Goods Sold (% of Revenue) | D46: =D14 -> 0.37 | E46: =E14 -> 0.38 | F46: =F14 -> 0.39 | G46: =G14 -> 0.4 | H46: =H14 -> 0.41 | I46: =CHOOSE($I$10,I14,I30) -> 0.42 | J46: =CHOOSE($I$10,J14,J30) -> 0.43 | K46: =CHOOSE($I$10,K14,K30) -> 0.44 | L46: =CHOOSE($I$10,L14,L30) -> 0.45 | M46: =CHOOSE($I$10,M14,M30) -> 0.46 | N46: =CHOOSE($I$10,N14,N30) -> 0.46 | O46: =CHOOSE($I$10,O14,O30) -> 0.42 | P46: =CHOOSE($I$10,P14,P30) -> 0.42
...

Sheet Target Model
D1: Historical Results | I1: Forecast Period | O1: Stub
A2: ='M&A Assumptions & Analysis'!D7&" Model" -> Brick 'n' Mortar Co Model | D2: 2020 | E2: =+D2+1 -> 2021 | F2: =+E2+1 -> 2022 | G2: =+F2+1 -> 2023 | H2: =+G2+1 -> 2024 | I2: =+H2+1 -> 2025 | J2: =+I2+1 -> 2026 | K2: =+J2+1 -> 2027 | L2: =+K2+1 -> 2028 | ... N2: =+M2+1 -> 2030 | O2: =+O4 -> 45838 | P2: =+P4 -> 46022
A3: Balance Sheet Check | D3: =IFERROR(IF(ABS(D101)>1,"ERROR","ok"),"ok") -> ok | E3: =IFERROR(IF(ABS(E101)>1,"ERROR","ok"),"ok") -> ok | F3: =IFERROR(IF(ABS(F101)>1,"ERROR","ok"),"ok") -> ok | G3: =IFERROR(IF(ABS(G101)>1,"ERROR","ok"),"ok") -> ok | H3: =IFERROR(IF(ABS(H101)>1,"ERROR","ok"),"ok") -> ok | I3: =IFERROR(IF(ABS(I101)>1,"ERROR","ok"),"ok") -> ok | J3: =IFERROR(IF(ABS(J101)>1,"ERROR","ok"),"ok") -> ok | K3: =IFERROR(IF(ABS(K101)>1,"ERROR","ok"),"ok") -> ok | ... N3: =IFERROR(IF(ABS(N101)>1,"ERROR","ok"),"ok") -> ok
A4: End of Period | D4: 41274 | E4: =EOMONTH(D4,12) -> 41639 | F4: =EOMONTH(E4,12) -> 42004 | G4: =EOMONTH(F4,12) -> 42369 | H4: =EOMONTH(G4,12) -> 42735 | I4: =EOMONTH(H4,12) -> 43100 | J4: =EOMONTH(I4,12) -> 43465 | K4: =EOMONTH(J4,12) -> 43830 | L4: =EOMONTH(K4,12) -> 44196 | ... N4: =EOMONTH(M4,12) -> 44926 | O4: =+'M&A Assumptions & Analysis'!D10 -> 45838 | P4: =+EOMONTH(O4,P6*12) -> 46022
A5: Days in Period | D5: 366 | E5: =E4-D4 -> 365 | F5: =F4-E4 -> 365 | G5: =G4-F4 -> 365 | H5: =H4-G4 -> 366 | I5: =I4-H4 -> 365 | J5: =J4-I4 -> 365 | K5: =K4-J4 -> 365 | L5: =L4-K4 -> 366 | ... N5: =N4-M4 -> 365 | O5: =+O4-H4 -> 3103 | P5: =+P4-O4 -> 184
A6: Fraction of Year | D6: 1 | E6: =D6 -> 1 | F6: =E6 -> 1 | G6: =F6 -> 1 | H6: =G6 -> 1 | I6: =H6 -> 1 | J6: =I6 -> 1 | K6: =J6 -> 1 | L6: =K6 -> 1 | ... N6: =M6 -> 1 | O6: 0.5 | P6: =1-O6 -> 0.5
A8: Assumptions
H10: LIVE SCENARIO | I10: 1
A12: SCENARIO 1
A13: Revenue Growth (% Change) | I13: 0.15 | J13: 0.15 | K13: 0.12 | L13: 0.1 | M13: 0.08 | N13: 0.06 | O13: 0.15 | P13: 0.15
A14: Cost of Goods Sold (% of Revenue) | I14: 0.42 | J14: 0.41 | K14: 0.4 | L14: 0.4 | M14: 0.4 | N14: 0.4 | O14: 0.42 | P14: 0.42
A15: Salaries and Benefits (% of Revenue) | I15: 0.16 | J15: 0.16 | K15: 0.16 | L15: 0.16 | M15: 0.16 | N15: 0.16 | O15: 0.16 | P15: 0.16
A16: Rent and Overhead ($000's) | I16: 7000 | J16: 7000 | K16: 7000 | L16: 7000 | M16: 7000 | N16: 7000 | O16: 7000 | P16: 7000
A17: Depreciation & Amortization (% of PP&E) | I17: 0.2 | J17: 0.2 | K17: 0.2 | L17: 0.2 | M17: 0.2 | N17: 0.2 | O17: 0.2 | P17: 0.2
A18: Interest (% of Debt) | I18: 0.08 | J18: 0.08 | K18: 0.08 | L18: 0.08 | M18: 0.08 | N18: 0.08 | O18: 0.08 | P18: 0.08
A19: Tax Rate (% of Earnings Before Tax) | I19: 0.32 | J19: 0.32 | K19: 0.32 | L19: 0.32 | M19: 0.32 | N19: 0.32 | O19: 0.32 | P19: 0.32
A20: Accounts Receivable (Days) | I20: 22 | J20: 18 | K20: 18 | L20: 18 | M20: 18 | N20: 18 | O20: 22 | P20: 22
A21: Inventory (Days) | I21: 75 | J21: 75 | K21: 75 | L21: 75 | M21: 75 | N21: 75 | O21: 75 | P21: 75
A22: Accounts Payable (Days) | I22: 39 | J22: 39 | K22: 39 | L22: 39 | M22: 39 | N22: 39 | O22: 39 | P22: 39
A23: Capital Expenditures ($000's) | I23: 5750 | J23: 5750 | K23: 5750 | L23: 5750 | M23: 5750 | N23: 5750 | O23: 5750 | P23: 5750
A24: Debt Issuance (Repayment) ($000's) | I24: 0 | J24: 0 | K24: 0 | L24: 0 | M24: 0 | N24: -10000 | O24: 0 | P24: 0
... A26: Payment of Dividends | I26: 0 | J26: 0 | K26: 0 | L26: 0 | M26: 200 | N26: 200 | O26: 0 | P26: 0
A28: SCENARIO 2
A29: Revenue Growth (% Change) | I29: 0.05 | J29: 0.045 | K29: 0.04 | L29: 0.035 | M29: 0.03 | N29: 0.03 | O29: 0.05 | P29: 0.05
A30: Cost of Goods Sold (% of Revenue) | I30: 0.37 | J30: 0.37 | K30: 0.36 | L30: 0.36 | M30: 0.35 | N30: 0.35 | O30: 0.37 | P30: 0.37
A31: Salaries and Benefits (% of Revenue) | I31: 0.17 | J31: 0.17 | K31: 0.17 | L31: 0.17 | M31: 0.17 | N31: 0.17 | O31: 0.17 | P31: 0.17
A32: Rent and Overhead ($000's) | I32: 10000 | J32: 10000 | K32: 10000 | L32: 10000 | M32: 10000 | N32: 10000 | O32: 10000 | P32: 10000
A33: Depreciation & Amortization (% of PP&E) | I33: 0.2 | J33: 0.2 | K33: 0.2 | L33: 0.2 | M33: 0.2 | N33: 0.2 | O33: 0.2 | P33: 0.2
A34: Interest (% of Debt) | I34: 0.05 | J34: 0.05 | K34: 0.05 | L34: 0.05 | M34: 0.05 | N34: 0.05 | O34: 0.05 | P34: 0.05
A35: Tax Rate (% of Earnings Before Tax) | I35: 0.28 | J35: 0.28 | K35: 0.28 | L35: 0.28 | M35: 0.28 | N35: 0.28 | O35: 0.28 | P35: 0.28
A36: Accounts Receivable (Days) | I36: 18 | J36: 18 | K36: 18 | L36: 18 | M36: 18 | N36: 18 | O36: 18 | P36: 18
A37: Inventory (Days) | I37: 73 | J37: 73 | K37: 73 | L37: 73 | M37: 73 | N37: 73 | O37: 73 | P37: 73
A38: Accounts Payable (Days) | I38: 37 | J38: 37 | K38: 37 | L38: 37 | M38: 37 | N38: 37 | O38: 37 | P38: 37
A39: Capital Expenditures ($000's) | I39: 15000 | J39: 15000 | K39: 15000 | L39: 15000 | M39: 15000 | N39: 15000 | O39: 15000 | P39: 15000
A40: Debt Issuance (Repayment) ($000's) | I40: 0 | J40: 0 | K40: -20000 | L40: 0 | M40: 0 | N40: 0 | O40: 0 | P40: 0
... A42: Payment of Dividends | I42: 0 | J42: 0 | K42: 0 | L42: 0 | M42: 100 | N42: 100 | O42: 0 | P42: 0
A44: LIVE SCENARIO
A45: Revenue Growth (% Change) | I45: =CHOOSE($I$10,I13,I29) -> 0.15 | J45: =CHOOSE($I$10,J13,J29) -> 0.15 | K45: =CHOOSE($I$10,K13,K29) -> 0.12 | L45: =CHOOSE($I$10,L13,L29) -> 0.1 | M45: =CHOOSE($I$10,M13,M29) -> 0.08 | N45: =CHOOSE($I$10,N13,N29) -> 0.06 | O45: =CHOOSE($I$10,O13,O29) -> 0.15 | P45: =CHOOSE($I$10,P13,P29) -> 0.15
A46: Cost of Goods Sold (% of Revenue) | I46: =CHOOSE($I$10,I14,I30) -> 0.42 | J46: =CHOOSE($I$10,J14,J30) -> 0.41 | K46: =CHOOSE($I$10,K14,K30) -> 0.4 | L46: =CHOOSE($I$10,L14,L30) -> 0.4 | M46: =CHOOSE($I$10,M14,M30) -> 0.4 | N46: =CHOOSE($I$10,N14,N30) -> 0.4 | O46: =CHOOSE($I$10,O14,O30) -> 0.42 | P46: =CHOOSE($I$10,P14,P30) -> 0.42
A47: Marketing, Advertising & Promotion (% of Revenue) | I47: =CHOOSE($I$10,I15,I31) -> 0.16 | J47: =CHOOSE($I$10,J15,J31) -> 0.16 | K47: =CHOOSE($I$10,K15,K31) -> 0.16 | L47: =CHOOSE($I$10,L15,L31) -> 0.16 | M47: =CHOOSE($I$10,M15,M31) -> 0.16 | N47: =CHOOSE($I$10,N15,N31) -> 0.16 | O47: =CHOOSE($I$10,O15,O31) -> 0.16 | P47: =CHOOSE($I$10,P15,P31) -> 0.16
...
